/home/marvin/Introduction_into_web_development/Abschlussprojekt/landwetter/scripts/dwd_sync.py:28: DeprecationWarning: datetime.datetime.utcnow() is deprecated and scheduled for removal in a future version. Use timezone-aware objects to represent datetimes in UTC: datetime.datetime.now(datetime.UTC).
  SOWING_DATE_STR = os.environ.get("SOWING_DATE", f"{datetime.utcnow().year}-05-01")
/home/marvin/Introduction_into_web_development/Abschlussprojekt/landwetter/scripts/dwd_sync.py:186: DeprecationWarning: datetime.datetime.utcnow() is deprecated and scheduled for removal in a future version. Use timezone-aware objects to represent datetimes in UTC: datetime.datetime.now(datetime.UTC).
  today = datetime.utcnow().date()
OK: station=10444 name=Goettingen lat=51.54 lon=9.93 balance=-10.6mm level=warnung state=gestresst (user=jz4u6saize7xupr)
/home/marvin/Introduction_into_web_development/Abschlussprojekt/landwetter/scripts/dwd_sync.py:28: DeprecationWarning: datetime.datetime.utcnow() is deprecated and scheduled for removal in a future version. Use timezone-aware objects to represent datetimes in UTC: datetime.datetime.now(datetime.UTC).
  SOWING_DATE_STR = os.environ.get("SOWING_DATE", f"{datetime.utcnow().year}-05-01")
Traceback (most recent call last):
  File "/home/marvin/Introduction_into_web_development/Abschlussprojekt/landwetter/scripts/dwd_sync.py", line 230, in <module>
    main()
  File "/home/marvin/Introduction_into_web_development/Abschlussprojekt/landwetter/scripts/dwd_sync.py", line 195, in main
    upsert("weather_snapshots", data, token, rid=None)
  File "/home/marvin/Introduction_into_web_development/Abschlussprojekt/landwetter/scripts/dwd_sync.py", line 54, in upsert
    r.raise_for_status()
  File "/home/marvin/Introduction_into_web_development/Abschlussprojekt/landwetter/scripts/.venv/lib/python3.12/site-packages/requests/models.py", line 1026, in raise_for_status
    raise HTTPError(http_error_msg, response=self)
requests.exceptions.HTTPError: 400 Client Error: Bad Request for url: http://localhost:8090/api/collections/weather_snapshots/records
OK: station=10444 name=Goettingen lat=51.54 lon=9.93 balance=-14.4mm level=warnung state=gestresst (user=jz4u6saize7xupr)
Traceback (most recent call last):
  File "/home/marvin/Introduction_into_web_development/Abschlussprojekt/landwetter/scripts/.venv/lib/python3.12/site-packages/urllib3/connection.py", line 198, in _new_conn
    sock = connection.create_connection(
           ^^^^^^^^^^^^^^^^^^^^^^^^^^^^^
  File "/home/marvin/Introduction_into_web_development/Abschlussprojekt/landwetter/scripts/.venv/lib/python3.12/site-packages/urllib3/util/connection.py", line 85, in create_connection
    raise err
  File "/home/marvin/Introduction_into_web_development/Abschlussprojekt/landwetter/scripts/.venv/lib/python3.12/site-packages/urllib3/util/connection.py", line 73, in create_connection
    sock.connect(sa)
ConnectionRefusedError: [Errno 111] Connection refused

The above exception was the direct cause of the following exception:

Traceback (most recent call last):
  File "/home/marvin/Introduction_into_web_development/Abschlussprojekt/landwetter/scripts/.venv/lib/python3.12/site-packages/urllib3/connectionpool.py", line 787, in urlopen
    response = self._make_request(
               ^^^^^^^^^^^^^^^^^^^
  File "/home/marvin/Introduction_into_web_development/Abschlussprojekt/landwetter/scripts/.venv/lib/python3.12/site-packages/urllib3/connectionpool.py", line 493, in _make_request
    conn.request(
  File "/home/marvin/Introduction_into_web_development/Abschlussprojekt/landwetter/scripts/.venv/lib/python3.12/site-packages/urllib3/connection.py", line 494, in request
    self.endheaders()
  File "/home/marvin/miniconda3/lib/python3.12/http/client.py", line 1326, in endheaders
    self._send_output(message_body, encode_chunked=encode_chunked)
  File "/home/marvin/miniconda3/lib/python3.12/http/client.py", line 1085, in _send_output
    self.send(msg)
  File "/home/marvin/miniconda3/lib/python3.12/http/client.py", line 1029, in send
    self.connect()
  File "/home/marvin/Introduction_into_web_development/Abschlussprojekt/landwetter/scripts/.venv/lib/python3.12/site-packages/urllib3/connection.py", line 325, in connect
    self.sock = self._new_conn()
                ^^^^^^^^^^^^^^^^
  File "/home/marvin/Introduction_into_web_development/Abschlussprojekt/landwetter/scripts/.venv/lib/python3.12/site-packages/urllib3/connection.py", line 213, in _new_conn
    raise NewConnectionError(
urllib3.exceptions.NewConnectionError: <urllib3.connection.HTTPConnection object at 0x7d38fe363110>: Failed to establish a new connection: [Errno 111] Connection refused

The above exception was the direct cause of the following exception:

Traceback (most recent call last):
  File "/home/marvin/Introduction_into_web_development/Abschlussprojekt/landwetter/scripts/.venv/lib/python3.12/site-packages/requests/adapters.py", line 644, in send
    resp = conn.urlopen(
           ^^^^^^^^^^^^^
  File "/home/marvin/Introduction_into_web_development/Abschlussprojekt/landwetter/scripts/.venv/lib/python3.12/site-packages/urllib3/connectionpool.py", line 841, in urlopen
    retries = retries.increment(
              ^^^^^^^^^^^^^^^^^^
  File "/home/marvin/Introduction_into_web_development/Abschlussprojekt/landwetter/scripts/.venv/lib/python3.12/site-packages/urllib3/util/retry.py", line 519, in increment
    raise MaxRetryError(_pool, url, reason) from reason  # type: ignore[arg-type]
    ^^^^^^^^^^^^^^^^^^^^^^^^^^^^^^^^^^^^^^^^^^^^^^^^^^^
urllib3.exceptions.MaxRetryError: HTTPConnectionPool(host='localhost', port=8090): Max retries exceeded with url: /api/collections/users/auth-with-password (Caused by NewConnectionError('<urllib3.connection.HTTPConnection object at 0x7d38fe363110>: Failed to establish a new connection: [Errno 111] Connection refused'))

During handling of the above exception, another exception occurred:

Traceback (most recent call last):
  File "/home/marvin/Introduction_into_web_development/Abschlussprojekt/landwetter/scripts/dwd_sync.py", line 257, in <module>
    main()
  File "/home/marvin/Introduction_into_web_development/Abschlussprojekt/landwetter/scripts/dwd_sync.py", line 191, in main
    token, user_id = user_login()
                     ^^^^^^^^^^^^
  File "/home/marvin/Introduction_into_web_development/Abschlussprojekt/landwetter/scripts/dwd_sync.py", line 35, in user_login
    r = requests.post(url, json={"identity": USER, "password": PASS}, timeout=20)
        ^^^^^^^^^^^^^^^^^^^^^^^^^^^^^^^^^^^^^^^^^^^^^^^^^^^^^^^^^^^^^^^^^^^^^^^^^
  File "/home/marvin/Introduction_into_web_development/Abschlussprojekt/landwetter/scripts/.venv/lib/python3.12/site-packages/requests/api.py", line 115, in post
    return request("post", url, data=data, json=json, **kwargs)
           ^^^^^^^^^^^^^^^^^^^^^^^^^^^^^^^^^^^^^^^^^^^^^^^^^^^^
  File "/home/marvin/Introduction_into_web_development/Abschlussprojekt/landwetter/scripts/.venv/lib/python3.12/site-packages/requests/api.py", line 59, in request
    return session.request(method=method, url=url, **kwargs)
           ^^^^^^^^^^^^^^^^^^^^^^^^^^^^^^^^^^^^^^^^^^^^^^^^^
  File "/home/marvin/Introduction_into_web_development/Abschlussprojekt/landwetter/scripts/.venv/lib/python3.12/site-packages/requests/sessions.py", line 589, in request
    resp = self.send(prep, **send_kwargs)
           ^^^^^^^^^^^^^^^^^^^^^^^^^^^^^^
  File "/home/marvin/Introduction_into_web_development/Abschlussprojekt/landwetter/scripts/.venv/lib/python3.12/site-packages/requests/sessions.py", line 703, in send
    r = adapter.send(request, **kwargs)
        ^^^^^^^^^^^^^^^^^^^^^^^^^^^^^^^
  File "/home/marvin/Introduction_into_web_development/Abschlussprojekt/landwetter/scripts/.venv/lib/python3.12/site-packages/requests/adapters.py", line 677, in send
    raise ConnectionError(e, request=request)
requests.exceptions.ConnectionError: HTTPConnectionPool(host='localhost', port=8090): Max retries exceeded with url: /api/collections/users/auth-with-password (Caused by NewConnectionError('<urllib3.connection.HTTPConnection object at 0x7d38fe363110>: Failed to establish a new connection: [Errno 111] Connection refused'))
Traceback (most recent call last):
  File "/home/marvin/Introduction_into_web_development/Abschlussprojekt/landwetter/scripts/.venv/lib/python3.12/site-packages/urllib3/connection.py", line 198, in _new_conn
    sock = connection.create_connection(
           ^^^^^^^^^^^^^^^^^^^^^^^^^^^^^
  File "/home/marvin/Introduction_into_web_development/Abschlussprojekt/landwetter/scripts/.venv/lib/python3.12/site-packages/urllib3/util/connection.py", line 85, in create_connection
    raise err
  File "/home/marvin/Introduction_into_web_development/Abschlussprojekt/landwetter/scripts/.venv/lib/python3.12/site-packages/urllib3/util/connection.py", line 73, in create_connection
    sock.connect(sa)
ConnectionRefusedError: [Errno 111] Connection refused

The above exception was the direct cause of the following exception:

Traceback (most recent call last):
  File "/home/marvin/Introduction_into_web_development/Abschlussprojekt/landwetter/scripts/.venv/lib/python3.12/site-packages/urllib3/connectionpool.py", line 787, in urlopen
    response = self._make_request(
               ^^^^^^^^^^^^^^^^^^^
  File "/home/marvin/Introduction_into_web_development/Abschlussprojekt/landwetter/scripts/.venv/lib/python3.12/site-packages/urllib3/connectionpool.py", line 493, in _make_request
    conn.request(
  File "/home/marvin/Introduction_into_web_development/Abschlussprojekt/landwetter/scripts/.venv/lib/python3.12/site-packages/urllib3/connection.py", line 494, in request
    self.endheaders()
  File "/home/marvin/miniconda3/lib/python3.12/http/client.py", line 1326, in endheaders
    self._send_output(message_body, encode_chunked=encode_chunked)
  File "/home/marvin/miniconda3/lib/python3.12/http/client.py", line 1085, in _send_output
    self.send(msg)
  File "/home/marvin/miniconda3/lib/python3.12/http/client.py", line 1029, in send
    self.connect()
  File "/home/marvin/Introduction_into_web_development/Abschlussprojekt/landwetter/scripts/.venv/lib/python3.12/site-packages/urllib3/connection.py", line 325, in connect
    self.sock = self._new_conn()
                ^^^^^^^^^^^^^^^^
  File "/home/marvin/Introduction_into_web_development/Abschlussprojekt/landwetter/scripts/.venv/lib/python3.12/site-packages/urllib3/connection.py", line 213, in _new_conn
    raise NewConnectionError(
urllib3.exceptions.NewConnectionError: <urllib3.connection.HTTPConnection object at 0x763a0a71e390>: Failed to establish a new connection: [Errno 111] Connection refused

The above exception was the direct cause of the following exception:

Traceback (most recent call last):
  File "/home/marvin/Introduction_into_web_development/Abschlussprojekt/landwetter/scripts/.venv/lib/python3.12/site-packages/requests/adapters.py", line 644, in send
    resp = conn.urlopen(
           ^^^^^^^^^^^^^
  File "/home/marvin/Introduction_into_web_development/Abschlussprojekt/landwetter/scripts/.venv/lib/python3.12/site-packages/urllib3/connectionpool.py", line 841, in urlopen
    retries = retries.increment(
              ^^^^^^^^^^^^^^^^^^
  File "/home/marvin/Introduction_into_web_development/Abschlussprojekt/landwetter/scripts/.venv/lib/python3.12/site-packages/urllib3/util/retry.py", line 519, in increment
    raise MaxRetryError(_pool, url, reason) from reason  # type: ignore[arg-type]
    ^^^^^^^^^^^^^^^^^^^^^^^^^^^^^^^^^^^^^^^^^^^^^^^^^^^
urllib3.exceptions.MaxRetryError: HTTPConnectionPool(host='localhost', port=8090): Max retries exceeded with url: /api/collections/users/auth-with-password (Caused by NewConnectionError('<urllib3.connection.HTTPConnection object at 0x763a0a71e390>: Failed to establish a new connection: [Errno 111] Connection refused'))

During handling of the above exception, another exception occurred:

Traceback (most recent call last):
  File "/home/marvin/Introduction_into_web_development/Abschlussprojekt/landwetter/scripts/dwd_sync.py", line 257, in <module>
    main()
  File "/home/marvin/Introduction_into_web_development/Abschlussprojekt/landwetter/scripts/dwd_sync.py", line 191, in main
    token, user_id = user_login()
                     ^^^^^^^^^^^^
  File "/home/marvin/Introduction_into_web_development/Abschlussprojekt/landwetter/scripts/dwd_sync.py", line 35, in user_login
    r = requests.post(url, json={"identity": USER, "password": PASS}, timeout=20)
        ^^^^^^^^^^^^^^^^^^^^^^^^^^^^^^^^^^^^^^^^^^^^^^^^^^^^^^^^^^^^^^^^^^^^^^^^^
  File "/home/marvin/Introduction_into_web_development/Abschlussprojekt/landwetter/scripts/.venv/lib/python3.12/site-packages/requests/api.py", line 115, in post
    return request("post", url, data=data, json=json, **kwargs)
           ^^^^^^^^^^^^^^^^^^^^^^^^^^^^^^^^^^^^^^^^^^^^^^^^^^^^
  File "/home/marvin/Introduction_into_web_development/Abschlussprojekt/landwetter/scripts/.venv/lib/python3.12/site-packages/requests/api.py", line 59, in request
    return session.request(method=method, url=url, **kwargs)
           ^^^^^^^^^^^^^^^^^^^^^^^^^^^^^^^^^^^^^^^^^^^^^^^^^
  File "/home/marvin/Introduction_into_web_development/Abschlussprojekt/landwetter/scripts/.venv/lib/python3.12/site-packages/requests/sessions.py", line 589, in request
    resp = self.send(prep, **send_kwargs)
           ^^^^^^^^^^^^^^^^^^^^^^^^^^^^^^
  File "/home/marvin/Introduction_into_web_development/Abschlussprojekt/landwetter/scripts/.venv/lib/python3.12/site-packages/requests/sessions.py", line 703, in send
    r = adapter.send(request, **kwargs)
        ^^^^^^^^^^^^^^^^^^^^^^^^^^^^^^^
  File "/home/marvin/Introduction_into_web_development/Abschlussprojekt/landwetter/scripts/.venv/lib/python3.12/site-packages/requests/adapters.py", line 677, in send
    raise ConnectionError(e, request=request)
requests.exceptions.ConnectionError: HTTPConnectionPool(host='localhost', port=8090): Max retries exceeded with url: /api/collections/users/auth-with-password (Caused by NewConnectionError('<urllib3.connection.HTTPConnection object at 0x763a0a71e390>: Failed to establish a new connection: [Errno 111] Connection refused'))
Traceback (most recent call last):
  File "/home/marvin/Introduction_into_web_development/Abschlussprojekt/landwetter/scripts/.venv/lib/python3.12/site-packages/urllib3/connection.py", line 198, in _new_conn
    sock = connection.create_connection(
           ^^^^^^^^^^^^^^^^^^^^^^^^^^^^^
  File "/home/marvin/Introduction_into_web_development/Abschlussprojekt/landwetter/scripts/.venv/lib/python3.12/site-packages/urllib3/util/connection.py", line 85, in create_connection
    raise err
  File "/home/marvin/Introduction_into_web_development/Abschlussprojekt/landwetter/scripts/.venv/lib/python3.12/site-packages/urllib3/util/connection.py", line 73, in create_connection
    sock.connect(sa)
ConnectionRefusedError: [Errno 111] Connection refused

The above exception was the direct cause of the following exception:

Traceback (most recent call last):
  File "/home/marvin/Introduction_into_web_development/Abschlussprojekt/landwetter/scripts/.venv/lib/python3.12/site-packages/urllib3/connectionpool.py", line 787, in urlopen
    response = self._make_request(
               ^^^^^^^^^^^^^^^^^^^
  File "/home/marvin/Introduction_into_web_development/Abschlussprojekt/landwetter/scripts/.venv/lib/python3.12/site-packages/urllib3/connectionpool.py", line 493, in _make_request
    conn.request(
  File "/home/marvin/Introduction_into_web_development/Abschlussprojekt/landwetter/scripts/.venv/lib/python3.12/site-packages/urllib3/connection.py", line 494, in request
    self.endheaders()
  File "/home/marvin/miniconda3/lib/python3.12/http/client.py", line 1326, in endheaders
    self._send_output(message_body, encode_chunked=encode_chunked)
  File "/home/marvin/miniconda3/lib/python3.12/http/client.py", line 1085, in _send_output
    self.send(msg)
  File "/home/marvin/miniconda3/lib/python3.12/http/client.py", line 1029, in send
    self.connect()
  File "/home/marvin/Introduction_into_web_development/Abschlussprojekt/landwetter/scripts/.venv/lib/python3.12/site-packages/urllib3/connection.py", line 325, in connect
    self.sock = self._new_conn()
                ^^^^^^^^^^^^^^^^
  File "/home/marvin/Introduction_into_web_development/Abschlussprojekt/landwetter/scripts/.venv/lib/python3.12/site-packages/urllib3/connection.py", line 213, in _new_conn
    raise NewConnectionError(
urllib3.exceptions.NewConnectionError: <urllib3.connection.HTTPConnection object at 0x709eeebe0800>: Failed to establish a new connection: [Errno 111] Connection refused

The above exception was the direct cause of the following exception:

Traceback (most recent call last):
  File "/home/marvin/Introduction_into_web_development/Abschlussprojekt/landwetter/scripts/.venv/lib/python3.12/site-packages/requests/adapters.py", line 644, in send
    resp = conn.urlopen(
           ^^^^^^^^^^^^^
  File "/home/marvin/Introduction_into_web_development/Abschlussprojekt/landwetter/scripts/.venv/lib/python3.12/site-packages/urllib3/connectionpool.py", line 841, in urlopen
    retries = retries.increment(
              ^^^^^^^^^^^^^^^^^^
  File "/home/marvin/Introduction_into_web_development/Abschlussprojekt/landwetter/scripts/.venv/lib/python3.12/site-packages/urllib3/util/retry.py", line 519, in increment
    raise MaxRetryError(_pool, url, reason) from reason  # type: ignore[arg-type]
    ^^^^^^^^^^^^^^^^^^^^^^^^^^^^^^^^^^^^^^^^^^^^^^^^^^^
urllib3.exceptions.MaxRetryError: HTTPConnectionPool(host='localhost', port=8090): Max retries exceeded with url: /api/collections/users/auth-with-password (Caused by NewConnectionError('<urllib3.connection.HTTPConnection object at 0x709eeebe0800>: Failed to establish a new connection: [Errno 111] Connection refused'))

During handling of the above exception, another exception occurred:

Traceback (most recent call last):
  File "/home/marvin/Introduction_into_web_development/Abschlussprojekt/landwetter/scripts/dwd_sync.py", line 257, in <module>
    main()
  File "/home/marvin/Introduction_into_web_development/Abschlussprojekt/landwetter/scripts/dwd_sync.py", line 191, in main
    token, user_id = user_login()
                     ^^^^^^^^^^^^
  File "/home/marvin/Introduction_into_web_development/Abschlussprojekt/landwetter/scripts/dwd_sync.py", line 35, in user_login
    r = requests.post(url, json={"identity": USER, "password": PASS}, timeout=20)
        ^^^^^^^^^^^^^^^^^^^^^^^^^^^^^^^^^^^^^^^^^^^^^^^^^^^^^^^^^^^^^^^^^^^^^^^^^
  File "/home/marvin/Introduction_into_web_development/Abschlussprojekt/landwetter/scripts/.venv/lib/python3.12/site-packages/requests/api.py", line 115, in post
    return request("post", url, data=data, json=json, **kwargs)
           ^^^^^^^^^^^^^^^^^^^^^^^^^^^^^^^^^^^^^^^^^^^^^^^^^^^^
  File "/home/marvin/Introduction_into_web_development/Abschlussprojekt/landwetter/scripts/.venv/lib/python3.12/site-packages/requests/api.py", line 59, in request
    return session.request(method=method, url=url, **kwargs)
           ^^^^^^^^^^^^^^^^^^^^^^^^^^^^^^^^^^^^^^^^^^^^^^^^^
  File "/home/marvin/Introduction_into_web_development/Abschlussprojekt/landwetter/scripts/.venv/lib/python3.12/site-packages/requests/sessions.py", line 589, in request
    resp = self.send(prep, **send_kwargs)
           ^^^^^^^^^^^^^^^^^^^^^^^^^^^^^^
  File "/home/marvin/Introduction_into_web_development/Abschlussprojekt/landwetter/scripts/.venv/lib/python3.12/site-packages/requests/sessions.py", line 703, in send
    r = adapter.send(request, **kwargs)
        ^^^^^^^^^^^^^^^^^^^^^^^^^^^^^^^
  File "/home/marvin/Introduction_into_web_development/Abschlussprojekt/landwetter/scripts/.venv/lib/python3.12/site-packages/requests/adapters.py", line 677, in send
    raise ConnectionError(e, request=request)
requests.exceptions.ConnectionError: HTTPConnectionPool(host='localhost', port=8090): Max retries exceeded with url: /api/collections/users/auth-with-password (Caused by NewConnectionError('<urllib3.connection.HTTPConnection object at 0x709eeebe0800>: Failed to establish a new connection: [Errno 111] Connection refused'))
Traceback (most recent call last):
  File "/home/marvin/Introduction_into_web_development/Abschlussprojekt/landwetter/scripts/.venv/lib/python3.12/site-packages/urllib3/connection.py", line 198, in _new_conn
    sock = connection.create_connection(
           ^^^^^^^^^^^^^^^^^^^^^^^^^^^^^
  File "/home/marvin/Introduction_into_web_development/Abschlussprojekt/landwetter/scripts/.venv/lib/python3.12/site-packages/urllib3/util/connection.py", line 85, in create_connection
    raise err
  File "/home/marvin/Introduction_into_web_development/Abschlussprojekt/landwetter/scripts/.venv/lib/python3.12/site-packages/urllib3/util/connection.py", line 73, in create_connection
    sock.connect(sa)
ConnectionRefusedError: [Errno 111] Connection refused

The above exception was the direct cause of the following exception:

Traceback (most recent call last):
  File "/home/marvin/Introduction_into_web_development/Abschlussprojekt/landwetter/scripts/.venv/lib/python3.12/site-packages/urllib3/connectionpool.py", line 787, in urlopen
    response = self._make_request(
               ^^^^^^^^^^^^^^^^^^^
  File "/home/marvin/Introduction_into_web_development/Abschlussprojekt/landwetter/scripts/.venv/lib/python3.12/site-packages/urllib3/connectionpool.py", line 493, in _make_request
    conn.request(
  File "/home/marvin/Introduction_into_web_development/Abschlussprojekt/landwetter/scripts/.venv/lib/python3.12/site-packages/urllib3/connection.py", line 494, in request
    self.endheaders()
  File "/home/marvin/miniconda3/lib/python3.12/http/client.py", line 1326, in endheaders
    self._send_output(message_body, encode_chunked=encode_chunked)
  File "/home/marvin/miniconda3/lib/python3.12/http/client.py", line 1085, in _send_output
    self.send(msg)
  File "/home/marvin/miniconda3/lib/python3.12/http/client.py", line 1029, in send
    self.connect()
  File "/home/marvin/Introduction_into_web_development/Abschlussprojekt/landwetter/scripts/.venv/lib/python3.12/site-packages/urllib3/connection.py", line 325, in connect
    self.sock = self._new_conn()
                ^^^^^^^^^^^^^^^^
  File "/home/marvin/Introduction_into_web_development/Abschlussprojekt/landwetter/scripts/.venv/lib/python3.12/site-packages/urllib3/connection.py", line 213, in _new_conn
    raise NewConnectionError(
urllib3.exceptions.NewConnectionError: <urllib3.connection.HTTPConnection object at 0x7f294b13eb10>: Failed to establish a new connection: [Errno 111] Connection refused

The above exception was the direct cause of the following exception:

Traceback (most recent call last):
  File "/home/marvin/Introduction_into_web_development/Abschlussprojekt/landwetter/scripts/.venv/lib/python3.12/site-packages/requests/adapters.py", line 644, in send
    resp = conn.urlopen(
           ^^^^^^^^^^^^^
  File "/home/marvin/Introduction_into_web_development/Abschlussprojekt/landwetter/scripts/.venv/lib/python3.12/site-packages/urllib3/connectionpool.py", line 841, in urlopen
    retries = retries.increment(
              ^^^^^^^^^^^^^^^^^^
  File "/home/marvin/Introduction_into_web_development/Abschlussprojekt/landwetter/scripts/.venv/lib/python3.12/site-packages/urllib3/util/retry.py", line 519, in increment
    raise MaxRetryError(_pool, url, reason) from reason  # type: ignore[arg-type]
    ^^^^^^^^^^^^^^^^^^^^^^^^^^^^^^^^^^^^^^^^^^^^^^^^^^^
urllib3.exceptions.MaxRetryError: HTTPConnectionPool(host='localhost', port=8090): Max retries exceeded with url: /api/collections/users/auth-with-password (Caused by NewConnectionError('<urllib3.connection.HTTPConnection object at 0x7f294b13eb10>: Failed to establish a new connection: [Errno 111] Connection refused'))

During handling of the above exception, another exception occurred:

Traceback (most recent call last):
  File "/home/marvin/Introduction_into_web_development/Abschlussprojekt/landwetter/scripts/dwd_sync.py", line 257, in <module>
    main()
  File "/home/marvin/Introduction_into_web_development/Abschlussprojekt/landwetter/scripts/dwd_sync.py", line 191, in main
    token, user_id = user_login()
                     ^^^^^^^^^^^^
  File "/home/marvin/Introduction_into_web_development/Abschlussprojekt/landwetter/scripts/dwd_sync.py", line 35, in user_login
    r = requests.post(url, json={"identity": USER, "password": PASS}, timeout=20)
        ^^^^^^^^^^^^^^^^^^^^^^^^^^^^^^^^^^^^^^^^^^^^^^^^^^^^^^^^^^^^^^^^^^^^^^^^^
  File "/home/marvin/Introduction_into_web_development/Abschlussprojekt/landwetter/scripts/.venv/lib/python3.12/site-packages/requests/api.py", line 115, in post
    return request("post", url, data=data, json=json, **kwargs)
           ^^^^^^^^^^^^^^^^^^^^^^^^^^^^^^^^^^^^^^^^^^^^^^^^^^^^
  File "/home/marvin/Introduction_into_web_development/Abschlussprojekt/landwetter/scripts/.venv/lib/python3.12/site-packages/requests/api.py", line 59, in request
    return session.request(method=method, url=url, **kwargs)
           ^^^^^^^^^^^^^^^^^^^^^^^^^^^^^^^^^^^^^^^^^^^^^^^^^
  File "/home/marvin/Introduction_into_web_development/Abschlussprojekt/landwetter/scripts/.venv/lib/python3.12/site-packages/requests/sessions.py", line 589, in request
    resp = self.send(prep, **send_kwargs)
           ^^^^^^^^^^^^^^^^^^^^^^^^^^^^^^
  File "/home/marvin/Introduction_into_web_development/Abschlussprojekt/landwetter/scripts/.venv/lib/python3.12/site-packages/requests/sessions.py", line 703, in send
    r = adapter.send(request, **kwargs)
        ^^^^^^^^^^^^^^^^^^^^^^^^^^^^^^^
  File "/home/marvin/Introduction_into_web_development/Abschlussprojekt/landwetter/scripts/.venv/lib/python3.12/site-packages/requests/adapters.py", line 677, in send
    raise ConnectionError(e, request=request)
requests.exceptions.ConnectionError: HTTPConnectionPool(host='localhost', port=8090): Max retries exceeded with url: /api/collections/users/auth-with-password (Caused by NewConnectionError('<urllib3.connection.HTTPConnection object at 0x7f294b13eb10>: Failed to establish a new connection: [Errno 111] Connection refused'))
